[2018/01/28 21:36:56] [?/INFO]: Calling pyexpander
[2018/01/28 21:36:57] [?/ERROR]: Command '['expander3.py', '-i', 'main.ccu']' returned non-zero exit status 1
Traceback (most recent call last):
  File "/mnt/c/Users/Austin-zs/Documents/Austin/powder game code/Programming/Python3/PyCharmGeneral/CCU2/main.py", line 69, in <module>
    main()
  File "/mnt/c/Users/Austin-zs/Documents/Austin/powder game code/Programming/Python3/PyCharmGeneral/CCU2/main.py", line 34, in main
    text, fileName, outputPath = Common.file.getContent()
  File "/mnt/c/Users/Austin-zs/Documents/Austin/powder game code/Programming/Python3/PyCharmGeneral/CCU2/Common/file.py", line 32, in getContent
    text = subprocess.check_output(["expander3.py", '-i', fileName])
  File "/usr/lib/python3.5/subprocess.py", line 626, in check_output
    **kwargs).stdout
  File "/usr/lib/python3.5/subprocess.py", line 708, in run
    output=stdout, stderr=stderr)
subprocess.CalledProcessError: Command '['expander3.py', '-i', 'main.ccu']' returned non-zero exit status 1
